Workbook

Sheet Master Schedule
A1: No | B1: Event | C1: DATE | D1: DAY | E1: SPORT | F1: TIME | G1: OPPONENT | H1: HOME OR AWAY | I1: Departure Time if Away | J1: Status
A2: 1 | C2: 46235 | D2: =text(C2,"dddd") -> Saturday | E2: =TEXTJOIN( CHAR(10) & CHAR(10), TRUE, IFERROR(WSO!E2, ""), IFERROR(MSO!E2, ""), IFERROR(FH!E2, ""), IFERROR(MGOLF!E2, ""), IFERROR(Football!E2, ""), IFERROR(WVB!E2, ""), IFERROR(XC!E2, ""), IFERROR(SWIMMING!E2, ""), IFERROR(WTEN!E2, ""), IFERROR(TF!E2, ""), IFERROR(WGOLF!E2, ""), IFERROR(WBB!E2, ""), IFERROR(MBB!E2, ""), IFERROR(WLAX!E2, ""), IFERROR(MLAX!E2, ""), IFERROR(SOFT!E2, ""), IFERROR(BASE!E2, ""), IFERROR(ESPORTS!E2, "") ) | F2: =IFERROR(__xludf.DUMMYFUNCTION("TEXTJOIN( CHAR(10) & CHAR(10), TRUE, IFERROR(TEXT(FILTER(WSO!F2, LEN(WSO!F2)), ""h:mm AM/PM""), """"), IFERROR(TEXT(FILTER(MSO!F2, LEN(MSO!F2)), ""h:mm AM/PM""), """"), IFERROR(TEXT(FILTER(FH!F2, LEN(FH!F2)), ""h:mm AM/PM""), """"), IFERROR(TE"&"XT(FILTER(MGOLF!F2, LEN(MGOLF!F2)), ""h:mm AM/PM""), """"), IFERROR(TEXT(FILTER(Football!F2, LEN(Football!F2)), ""h:mm AM/PM""), """"), IFERROR(TEXT(FILTER(WVB!F2, LEN(WVB!F2)), ""h:mm AM/PM""), """"), IFERROR(TEXT(FILTER(XC!F2, LEN(XC!F2)), ""h:mm "&"AM/PM""), """"), IFERROR(TEXT(FILTER(SWIMMING!F2, LEN(SWIMMING!F2)), ""h:mm AM/PM""), """"), IFERROR(TEXT(FILTER(WTEN!F2, LEN(WTEN!F2)), ""h:mm AM/PM""), """"), IFERROR(TEXT(FILTER(TF!F2, LEN(TF!F2)), ""h:mm AM/PM""), """"), IFERROR(TEXT(FILTER(WG"&"OLF!F2, LEN(WGOLF!F2)), ""h:mm AM/PM""), """"), IFERROR(TEXT(FILTER(WBB!F2, LEN(WBB!F2)), ""h:mm AM/PM""), """"), IFERROR(TEXT(FILTER(MBB!F2, LEN(MBB!F2)), ""h:mm AM/PM""), """"), IFERROR(TEXT(FILTER(WLAX!F2, LEN(WLAX!F2)), ""h:mm AM/PM""), """"), "&" IFERROR(TEXT(FILTER(MLAX!F2, LEN(MLAX!F2)), ""h:mm AM/PM""), """"), IFERROR(TEXT(FILTER(SOFT!F2, LEN(SOFT!F2)), ""h:mm AM/PM""), """"), IFERROR(TEXT(FILTER(BASE!F2, LEN(BASE!F2)), ""h:mm AM/PM""), """"), IFERROR(TEXT(FILTER(ESPORTS!F2, LEN(ESPORTS!"&"F2)), ""h:mm AM/PM""), """") ) "),"") | G2: =IFERROR(__xludf.DUMMYFUNCTION("TEXTJOIN( CHAR(10) & CHAR(10), TRUE, IFERROR(FILTER(WSO!G2, LEN(WSO!G2)), """"), IFERROR(FILTER(MSO!G2, LEN(MSO!G2)), """"), IFERROR(FILTER(FH!G2, LEN(FH!G2)), """"), IFERROR(FILTER(MGOLF!G2, LEN(MGOLF!G2)), """"), IFERROR(FILTER(Football!G2"&", LEN(Football!G2)), """"), IFERROR(FILTER(WVB!G2, LEN(WVB!G2)), """"), IFERROR(FILTER(XC!G2, LEN(XC!G2)), """"), IFERROR(FILTER(SWIMMING!G2, LEN(SWIMMING!G2)), """"), IFERROR(FILTER(WTEN!G2, LEN(WTEN!G2)), """"), IFERROR(FILTER(TF!G2, LEN(TF!G2"&")), """"), IFERROR(FILTER(WGOLF!G2:G1000, LEN(WGOLF!G2)), """"), IFERROR(FILTER(WBB!G2, LEN(WBB!G2)), """"), IFERROR(FILTER(MBB!G2, LEN(MBB!G2)), """"), IFERROR(FILTER(WLAX!G2, LEN(WLAX!G2)), """"), IFERROR(FILTER(MLAX!G2, LEN(MLAX!G2)), """"), "&" IFERROR(FILTER(SOFT!G2, LEN(SOFT!G2)), """"), IFERROR(FILTER(BASE!G2, LEN(BASE!G2)), """"), IFERROR(FILTER(ESPORTS!G2, LEN(ESPORTS!G2)), """") ) "),"") | H2: =IFERROR(__xludf.DUMMYFUNCTION("TEXTJOIN( CHAR(10) & CHAR(10), TRUE, IFERROR(FILTER(WSO!H2, LEN(WSO!H2)), """"), IFERROR(FILTER(MSO!H2, LEN(MSO!H2)), """"), IFERROR(FILTER(FH!H2, LEN(FH!H2)), """"), IFERROR(FILTER(MGOLF!H2, LEN(MGOLF!H2)), """"), IFERROR(FILTER(Football!H2"&", LEN(Football!H2)), """"), IFERROR(FILTER(WVB!H2, LEN(WVB!H2)), """"), IFERROR(FILTER(XC!H2, LEN(XC!H2)), """"), IFERROR(FILTER(SWIMMING!H2, LEN(SWIMMING!H2)), """"), IFERROR(FILTER(WTEN!H2, LEN(WTEN!H2)), """"), IFERROR(FILTER(TF!H2, LEN(TF!H2"&")), """"), IFERROR(FILTER(WGOLF!H2, LEN(WGOLF!H2)), """"), IFERROR(FILTER(WBB!H2, LEN(WBB!H2)), """"), IFERROR(FILTER(MBB!H2, LEN(MBB!H2)), """"), IFERROR(FILTER(WLAX!H2, LEN(WLAX!H2)), """"), IFERROR(FILTER(MLAX!H2, LEN(MLAX!H2)), """"), IFER"&"ROR(FILTER(SOFT!H2, LEN(SOFT!H2)), """"), IFERROR(FILTER(BASE!H2, LEN(BASE!H2)), """"), IFERROR(FILTER(ESPORTS!H2, LEN(ESPORTS!H2)), """") ) "),"") | I2: =IFERROR(__xludf.DUMMYFUNCTION("TEXTJOIN( CHAR(10) & CHAR(10), TRUE, IFERROR(ARRAYFORMULA(TEXT(FILTER(WSO!F2, LEN(WSO!F2)), ""h:mm AM/PM"")), """"), IFERROR(ARRAYFORMULA(TEXT(FILTER(MSO!F2, LEN(MSO!F2)), ""h:mm AM/PM"")), """"), IFERROR(ARRAYFORMULA(TEXT(FILTER(FH!F2, LEN(FH!F"&"2)), ""h:mm AM/PM"")), """"), IFERROR(ARRAYFORMULA(TEXT(FILTER(MGOLF!F2, LEN(MGOLF!F2)), ""h:mm AM/PM"")), """"), IFERROR(ARRAYFORMULA(TEXT(FILTER(Football!F2, LEN(Football!F2)), ""h:mm AM/PM"")), """"), IFERROR(ARRAYFORMULA(TEXT(FILTER(WVB!F2, LEN("&"WVB!F2)), ""h:mm AM/PM"")), """"), IFERROR(ARRAYFORMULA(TEXT(FILTER(XC!F2, LEN(XC!F2)), ""h:mm AM/PM"")), """"), IFERROR(ARRAYFORMULA(TEXT(FILTER(SWIMMING!F2, LEN(SWIMMING!F2)), ""h:mm AM/PM"")), """"), IFERROR(ARRAYFORMULA(TEXT(FILTER(WTEN!F2, LEN("&"WTEN!F2)), ""h:mm AM/PM"")), """"), IFERROR(ARRAYFORMULA(TEXT(FILTER(TF!F2, LEN(TF!F2)), ""h:mm AM/PM"")), """"), IFERROR(ARRAYFORMULA(TEXT(FILTER(WGOLF!F2, LEN(WGOLF!F2)), ""h:mm AM/PM"")), """"), IFERROR(ARRAYFORMULA(TEXT(FILTER(WBB!F2, LEN(WBB!F2"&")), ""h:mm AM/PM"")), """"), IFERROR(ARRAYFORMULA(TEXT(FILTER(MBB!F2, LEN(MBB!F2)), ""h:mm AM/PM"")), """"), IFERROR(ARRAYFORMULA(TEXT(FILTER(WLAX!F2, LEN(WLAX!F2)), ""h:mm AM/PM"")), """"), IFERROR(ARRAYFORMULA(TEXT(FILTER(MLAX!F2, LEN(MLAX!F2)), "&"""h:mm AM/PM"")), """"), IFERROR(ARRAYFORMULA(TEXT(FILTER(SOFT!F2, LEN(SOFT!F2)), ""h:mm AM/PM"")), """"), IFERROR(ARRAYFORMULA(TEXT(FILTER(BASE!F2, LEN(BASE!F2)), ""h:mm AM/PM"")), """"), IFERROR(ARRAYFORMULA(TEXT(FILTER(ESPORTS!F2, LEN(ESPORTS!F2)"&"), ""h:mm AM/PM"")), """") ) "),"") | J2: =IFERROR(__xludf.DUMMYFUNCTION("IFERROR( TEXTJOIN( CHAR(10) & CHAR(10), TRUE, FILTER( FLATTEN({ WSO!P2; MSO!P2; FH!P2; MGOLF!P2; Football!P2; WVB!P2; XC!P2; SWIMMING!P2; WTEN!P2; TF!P2; WGOLF!P2;"&" WBB!P2; MBB!P2; WLAX!P2; MLAX!P2; SOFT!P2; BASE!P2; ESPORTS!P2 }), (FLATTEN({ WSO!P2; MSO!P2; FH!P2; MGOLF!P2; Football!P2; WVB!P2; XC!P2; "&"SWIMMING!P2; WTEN!P2; TF!P2; WGOLF!P2; WBB!P2; MBB!P2; WLAX!P2; MLAX!P2; SOFT!P2; BASE!P2; ESPORTS!P2 }) <> """") * (FLATTEN({ WSO!P2; MSO!P2; FH!P2; "&" MGOLF!P2; Football!P2; WVB!P2; XC!P2; SWIMMING!P2; WTEN!P2; TF!P2; WGOLF!P2; WBB!P2; MBB!P2; WLAX!P2; MLAX!P2; SOFT!P2; BASE!P2; ESPORTS!P2 }) <> ""S"&"tatus"") ) ), """" ) "),"")
A3: 2 | C3: 46236 | D3: =text(C3,"dddd") -> Sunday | E3: =TEXTJOIN( CHAR(10) & CHAR(10), TRUE, IFERROR(WSO!E3, ""), IFERROR(MSO!E3, ""), IFERROR(FH!E3, ""), IFERROR(MGOLF!E3, ""), IFERROR(Football!E3, ""), IFERROR(WVB!E3, ""), IFERROR(XC!E3, ""), IFERROR(SWIMMING!E3, ""), IFERROR(WTEN!E3, ""), IFERROR(TF!E3, ""), IFERROR(WGOLF!E3, ""), IFERROR(WBB!E3, ""), IFERROR(MBB!E3, ""), IFERROR(WLAX!E3, ""), IFERROR(MLAX!E3, ""), IFERROR(SOFT!E3, ""), IFERROR(BASE!E3, ""), IFERROR(ESPORTS!E3, "") ) | F3: =IFERROR(__xludf.DUMMYFUNCTION("TEXTJOIN( CHAR(10) & CHAR(10), TRUE, IFERROR(TEXT(FILTER(WSO!F3, LEN(WSO!F3)), ""h:mm AM/PM""), """"), IFERROR(TEXT(FILTER(MSO!F3, LEN(MSO!F3)), ""h:mm AM/PM""), """"), IFERROR(TEXT(FILTER(FH!F3, LEN(FH!F3)), ""h:mm AM/PM""), """"), IFERROR(TE"&"XT(FILTER(MGOLF!F3, LEN(MGOLF!F3)), ""h:mm AM/PM""), """"), IFERROR(TEXT(FILTER(Football!F3, LEN(Football!F3)), ""h:mm AM/PM""), """"), IFERROR(TEXT(FILTER(WVB!F3, LEN(WVB!F3)), ""h:mm AM/PM""), """"), IFERROR(TEXT(FILTER(XC!F3, LEN(XC!F3)), ""h:mm "&"AM/PM""), """"), IFERROR(TEXT(FILTER(SWIMMING!F3, LEN(SWIMMING!F3)), ""h:mm AM/PM""), """"), IFERROR(TEXT(FILTER(WTEN!F3, LEN(WTEN!F3)), ""h:mm AM/PM""), """"), IFERROR(TEXT(FILTER(TF!F3, LEN(TF!F3)), ""h:mm AM/PM""), """"), IFERROR(TEXT(FILTER(WG"&"OLF!F3, LEN(WGOLF!F3)), ""h:mm AM/PM""), """"), IFERROR(TEXT(FILTER(WBB!F3, LEN(WBB!F3)), ""h:mm AM/PM""), """"), IFERROR(TEXT(FILTER(MBB!F3, LEN(MBB!F3)), ""h:mm AM/PM""), """"), IFERROR(TEXT(FILTER(WLAX!F3, LEN(WLAX!F3)), ""h:mm AM/PM""), """"), "&" IFERROR(TEXT(FILTER(MLAX!F3, LEN(MLAX!F3)), ""h:mm AM/PM""), """"), IFERROR(TEXT(FILTER(SOFT!F3, LEN(SOFT!F3)), ""h:mm AM/PM""), """"), IFERROR(TEXT(FILTER(BASE!F3, LEN(BASE!F3)), ""h:mm AM/PM""), """"), IFERROR(TEXT(FILTER(ESPORTS!F3, LEN(ESPORTS!"&"F3)), ""h:mm AM/PM""), """") ) "),"") | G3: =IFERROR(__xludf.DUMMYFUNCTION("TEXTJOIN( CHAR(10) & CHAR(10), TRUE, IFERROR(FILTER(WSO!G3, LEN(WSO!G3)), """"), IFERROR(FILTER(MSO!G3, LEN(MSO!G3)), """"), IFERROR(FILTER(FH!G3, LEN(FH!G3)), """"), IFERROR(FILTER(MGOLF!G3, LEN(MGOLF!G3)), """"), IFERROR(FILTER(Football!G3"&", LEN(Football!G3)), """"), IFERROR(FILTER(WVB!G3, LEN(WVB!G3)), """"), IFERROR(FILTER(XC!G3, LEN(XC!G3)), """"), IFERROR(FILTER(SWIMMING!G3, LEN(SWIMMING!G3)), """"), IFERROR(FILTER(WTEN!G3, LEN(WTEN!G3)), """"), IFERROR(FILTER(TF!G3, LEN(TF!G3"&")), """"), IFERROR(FILTER(WGOLF!G3:G1000, LEN(WGOLF!G3)), """"), IFERROR(FILTER(WBB!G3, LEN(WBB!G3)), """"), IFERROR(FILTER(MBB!G3, LEN(MBB!G3)), """"), IFERROR(FILTER(WLAX!G3, LEN(WLAX!G3)), """"), IFERROR(FILTER(MLAX!G3, LEN(MLAX!G3)), """"), "&" IFERROR(FILTER(SOFT!G3, LEN(SOFT!G3)), """"), IFERROR(FILTER(BASE!G3, LEN(BASE!G3)), """"), IFERROR(FILTER(ESPORTS!G3, LEN(ESPORTS!G3)), """") ) "),"") | H3: =IFERROR(__xludf.DUMMYFUNCTION("TEXTJOIN( CHAR(10) & CHAR(10), TRUE, IFERROR(FILTER(WSO!H3, LEN(WSO!H3)), """"), IFERROR(FILTER(MSO!H3, LEN(MSO!H3)), """"), IFERROR(FILTER(FH!H3, LEN(FH!H3)), """"), IFERROR(FILTER(MGOLF!H3, LEN(MGOLF!H3)), """"), IFERROR(FILTER(Football!H3"&", LEN(Football!H3)), """"), IFERROR(FILTER(WVB!H3, LEN(WVB!H3)), """"), IFERROR(FILTER(XC!H3, LEN(XC!H3)), """"), IFERROR(FILTER(SWIMMING!H3, LEN(SWIMMING!H3)), """"), IFERROR(FILTER(WTEN!H3, LEN(WTEN!H3)), """"), IFERROR(FILTER(TF!H3, LEN(TF!H3"&")), """"), IFERROR(FILTER(WGOLF!H3, LEN(WGOLF!H3)), """"), IFERROR(FILTER(WBB!H3, LEN(WBB!H3)), """"), IFERROR(FILTER(MBB!H3, LEN(MBB!H3)), """"), IFERROR(FILTER(WLAX!H3, LEN(WLAX!H3)), """"), IFERROR(FILTER(MLAX!H3, LEN(MLAX!H3)), """"), IFER"&"ROR(FILTER(SOFT!H3, LEN(SOFT!H3)), """"), IFERROR(FILTER(BASE!H3, LEN(BASE!H3)), """"), IFERROR(FILTER(ESPORTS!H3, LEN(ESPORTS!H3)), """") ) "),"") | I3: =IFERROR(__xludf.DUMMYFUNCTION("TEXTJOIN( CHAR(10) & CHAR(10), TRUE, IFERROR(ARRAYFORMULA(TEXT(FILTER(WSO!F3, LEN(WSO!F3)), ""h:mm AM/PM"")), """"), IFERROR(ARRAYFORMULA(TEXT(FILTER(MSO!F3, LEN(MSO!F3)), ""h:mm AM/PM"")), """"), IFERROR(ARRAYFORMULA(TEXT(FILTER(FH!F3, LEN(FH!F"&"3)), ""h:mm AM/PM"")), """"), IFERROR(ARRAYFORMULA(TEXT(FILTER(MGOLF!F3, LEN(MGOLF!F3)), ""h:mm AM/PM"")), """"), IFERROR(ARRAYFORMULA(TEXT(FILTER(Football!F3, LEN(Football!F3)), ""h:mm AM/PM"")), """"), IFERROR(ARRAYFORMULA(TEXT(FILTER(WVB!F3, LEN("&"WVB!F3)), ""h:mm AM/PM"")), """"), IFERROR(ARRAYFORMULA(TEXT(FILTER(XC!F3, LEN(XC!F3)), ""h:mm AM/PM"")), """"), IFERROR(ARRAYFORMULA(TEXT(FILTER(SWIMMING!F3, LEN(SWIMMING!F3)), ""h:mm AM/PM"")), """"), IFERROR(ARRAYFORMULA(TEXT(FILTER(WTEN!F3, LEN("&"WTEN!F3)), ""h:mm AM/PM"")), """"), IFERROR(ARRAYFORMULA(TEXT(FILTER(TF!F3, LEN(TF!F3)), ""h:mm AM/PM"")), """"), IFERROR(ARRAYFORMULA(TEXT(FILTER(WGOLF!F3, LEN(WGOLF!F3)), ""h:mm AM/PM"")), """"), IFERROR(ARRAYFORMULA(TEXT(FILTER(WBB!F3, LEN(WBB!F3"&")), ""h:mm AM/PM"")), """"), IFERROR(ARRAYFORMULA(TEXT(FILTER(MBB!F3, LEN(MBB!F3)), ""h:mm AM/PM"")), """"), IFERROR(ARRAYFORMULA(TEXT(FILTER(WLAX!F3, LEN(WLAX!F3)), ""h:mm AM/PM"")), """"), IFERROR(ARRAYFORMULA(TEXT(FILTER(MLAX!F3, LEN(MLAX!F3)), "&"""h:mm AM/PM"")), """"), IFERROR(ARRAYFORMULA(TEXT(FILTER(SOFT!F3, LEN(SOFT!F3)), ""h:mm AM/PM"")), """"), IFERROR(ARRAYFORMULA(TEXT(FILTER(BASE!F3, LEN(BASE!F3)), ""h:mm AM/PM"")), """"), IFERROR(ARRAYFORMULA(TEXT(FILTER(ESPORTS!F3, LEN(ESPORTS!F3)"&"), ""h:mm AM/PM"")), """") ) "),"") | J3: =IFERROR(__xludf.DUMMYFUNCTION("IFERROR( TEXTJOIN( CHAR(10) & CHAR(10), TRUE, FILTER( FLATTEN({ WSO!P3; MSO!P3; FH!P3; MGOLF!P3; Football!P3; WVB!P3; XC!P3; SWIMMING!P3; WTEN!P3; TF!P3; WGOLF!P3;"&" WBB!P3; MBB!P3; WLAX!P3; MLAX!P3; SOFT!P3; BASE!P3; ESPORTS!P3 }), (FLATTEN({ WSO!P3; MSO!P3; FH!P3; MGOLF!P3; Football!P3; WVB!P3; XC!P3; "&"SWIMMING!P3; WTEN!P3; TF!P3; WGOLF!P3; WBB!P3; MBB!P3; WLAX!P3; MLAX!P3; SOFT!P3; BASE!P3; ESPORTS!P3 }) <> """") * (FLATTEN({ WSO!P3; MSO!P3; FH!P3; "&" MGOLF!P3; Football!P3; WVB!P3; XC!P3; SWIMMING!P3; WTEN!P3; TF!P3; WGOLF!P3; WBB!P3; MBB!P3; WLAX!P3; MLAX!P3; SOFT!P3; BASE!P3; ESPORTS!P3 }) <> ""S"&"tatus"") ) ), """" ) "),"")
A4: 3 | C4: 46237 | D4: =text(C4,"dddd") -> Monday | E4: =TEXTJOIN( CHAR(10) & CHAR(10), TRUE, IFERROR(WSO!E4, ""), IFERROR(MSO!E4, ""), IFERROR(FH!E4, ""), IFERROR(MGOLF!E4, ""), IFERROR(Football!E4, ""), IFERROR(WVB!E4, ""), IFERROR(XC!E4, ""), IFERROR(SWIMMING!E4, ""), IFERROR(WTEN!E4, ""), IFERROR(TF!E4, ""), IFERROR(WGOLF!E4, ""), IFERROR(WBB!E4, ""), IFERROR(MBB!E4, ""), IFERROR(WLAX!E4, ""), IFERROR(MLAX!E4, ""), IFERROR(SOFT!E4, ""), IFERROR(BASE!E4, ""), IFERROR(ESPORTS!E4, "") ) | F4: =IFERROR(__xludf.DUMMYFUNCTION("TEXTJOIN( CHAR(10) & CHAR(10), TRUE, IFERROR(TEXT(FILTER(WSO!F4, LEN(WSO!F4)), ""h:mm AM/PM""), """"), IFERROR(TEXT(FILTER(MSO!F4, LEN(MSO!F4)), ""h:mm AM/PM""), """"), IFERROR(TEXT(FILTER(FH!F4, LEN(FH!F4)), ""h:mm AM/PM""), """"), IFERROR(TE"&"XT(FILTER(MGOLF!F4, LEN(MGOLF!F4)), ""h:mm AM/PM""), """"), IFERROR(TEXT(FILTER(Football!F4, LEN(Football!F4)), ""h:mm AM/PM""), """"), IFERROR(TEXT(FILTER(WVB!F4, LEN(WVB!F4)), ""h:mm AM/PM""), """"), IFERROR(TEXT(FILTER(XC!F4, LEN(XC!F4)), ""h:mm "&"AM/PM""), """"), IFERROR(TEXT(FILTER(SWIMMING!F4, LEN(SWIMMING!F4)), ""h:mm AM/PM""), """"), IFERROR(TEXT(FILTER(WTEN!F4, LEN(WTEN!F4)), ""h:mm AM/PM""), """"), IFERROR(TEXT(FILTER(TF!F4, LEN(TF!F4)), ""h:mm AM/PM""), """"), IFERROR(TEXT(FILTER(WG"&"OLF!F4, LEN(WGOLF!F4)), ""h:mm AM/PM""), """"), IFERROR(TEXT(FILTER(WBB!F4, LEN(WBB!F4)), ""h:mm AM/PM""), """"), IFERROR(TEXT(FILTER(MBB!F4, LEN(MBB!F4)), ""h:mm AM/PM""), """"), IFERROR(TEXT(FILTER(WLAX!F4, LEN(WLAX!F4)), ""h:mm AM/PM""), """"), "&" IFERROR(TEXT(FILTER(MLAX!F4, LEN(MLAX!F4)), ""h:mm AM/PM""), """"), IFERROR(TEXT(FILTER(SOFT!F4, LEN(SOFT!F4)), ""h:mm AM/PM""), """"), IFERROR(TEXT(FILTER(BASE!F4, LEN(BASE!F4)), ""h:mm AM/PM""), """"), IFERROR(TEXT(FILTER(ESPORTS!F4, LEN(ESPORTS!"&"F4)), ""h:mm AM/PM""), """") ) "),"") | G4: =IFERROR(__xludf.DUMMYFUNCTION("TEXTJOIN( CHAR(10) & CHAR(10), TRUE, IFERROR(FILTER(WSO!G4, LEN(WSO!G4)), """"), IFERROR(FILTER(MSO!G4, LEN(MSO!G4)), """"), IFERROR(FILTER(FH!G4, LEN(FH!G4)), """"), IFERROR(FILTER(MGOLF!G4, LEN(MGOLF!G4)), """"), IFERROR(FILTER(Football!G4"&", LEN(Football!G4)), """"), IFERROR(FILTER(WVB!G4, LEN(WVB!G4)), """"), IFERROR(FILTER(XC!G4, LEN(XC!G4)), """"), IFERROR(FILTER(SWIMMING!G4, LEN(SWIMMING!G4)), """"), IFERROR(FILTER(WTEN!G4, LEN(WTEN!G4)), """"), IFERROR(FILTER(TF!G4, LEN(TF!G4"&")), """"), IFERROR(FILTER(WGOLF!G4:G1000, LEN(WGOLF!G4)), """"), IFERROR(FILTER(WBB!G4, LEN(WBB!G4)), """"), IFERROR(FILTER(MBB!G4, LEN(MBB!G4)), """"), IFERROR(FILTER(WLAX!G4, LEN(WLAX!G4)), """"), IFERROR(FILTER(MLAX!G4, LEN(MLAX!G4)), """"), "&" IFERROR(FILTER(SOFT!G4, LEN(SOFT!G4)), """"), IFERROR(FILTER(BASE!G4, LEN(BASE!G4)), """"), IFERROR(FILTER(ESPORTS!G4, LEN(ESPORTS!G4)), """") ) "),"") | H4: =IFERROR(__xludf.DUMMYFUNCTION("TEXTJOIN( CHAR(10) & CHAR(10), TRUE, IFERROR(FILTER(WSO!H4, LEN(WSO!H4)), """"), IFERROR(FILTER(MSO!H4, LEN(MSO!H4)), """"), IFERROR(FILTER(FH!H4, LEN(FH!H4)), """"), IFERROR(FILTER(MGOLF!H4, LEN(MGOLF!H4)), """"), IFERROR(FILTER(Football!H4"&", LEN(Football!H4)), """"), IFERROR(FILTER(WVB!H4, LEN(WVB!H4)), """"), IFERROR(FILTER(XC!H4, LEN(XC!H4)), """"), IFERROR(FILTER(SWIMMING!H4, LEN(SWIMMING!H4)), """"), IFERROR(FILTER(WTEN!H4, LEN(WTEN!H4)), """"), IFERROR(FILTER(TF!H4, LEN(TF!H4"&")), """"), IFERROR(FILTER(WGOLF!H4, LEN(WGOLF!H4)), """"), IFERROR(FILTER(WBB!H4, LEN(WBB!H4)), """"), IFERROR(FILTER(MBB!H4, LEN(MBB!H4)), """"), IFERROR(FILTER(WLAX!H4, LEN(WLAX!H4)), """"), IFERROR(FILTER(MLAX!H4, LEN(MLAX!H4)), """"), IFER"&"ROR(FILTER(SOFT!H4, LEN(SOFT!H4)), """"), IFERROR(FILTER(BASE!H4, LEN(BASE!H4)), """"), IFERROR(FILTER(ESPORTS!H4, LEN(ESPORTS!H4)), """") ) "),"") | I4: =IFERROR(__xludf.DUMMYFUNCTION("TEXTJOIN( CHAR(10) & CHAR(10), TRUE, IFERROR(ARRAYFORMULA(TEXT(FILTER(WSO!F4, LEN(WSO!F4)), ""h:mm AM/PM"")), """"), IFERROR(ARRAYFORMULA(TEXT(FILTER(MSO!F4, LEN(MSO!F4)), ""h:mm AM/PM"")), """"), IFERROR(ARRAYFORMULA(TEXT(FILTER(FH!F4, LEN(FH!F"&"4)), ""h:mm AM/PM"")), """"), IFERROR(ARRAYFORMULA(TEXT(FILTER(MGOLF!F4, LEN(MGOLF!F4)), ""h:mm AM/PM"")), """"), IFERROR(ARRAYFORMULA(TEXT(FILTER(Football!F4, LEN(Football!F4)), ""h:mm AM/PM"")), """"), IFERROR(ARRAYFORMULA(TEXT(FILTER(WVB!F4, LEN("&"WVB!F4)), ""h:mm AM/PM"")), """"), IFERROR(ARRAYFORMULA(TEXT(FILTER(XC!F4, LEN(XC!F4)), ""h:mm AM/PM"")), """"), IFERROR(ARRAYFORMULA(TEXT(FILTER(SWIMMING!F4, LEN(SWIMMING!F4)), ""h:mm AM/PM"")), """"), IFERROR(ARRAYFORMULA(TEXT(FILTER(WTEN!F4, LEN("&"WTEN!F4)), ""h:mm AM/PM"")), """"), IFERROR(ARRAYFORMULA(TEXT(FILTER(TF!F4, LEN(TF!F4)), ""h:mm AM/PM"")), """"), IFERROR(ARRAYFORMULA(TEXT(FILTER(WGOLF!F4, LEN(WGOLF!F4)), ""h:mm AM/PM"")), """"), IFERROR(ARRAYFORMULA(TEXT(FILTER(WBB!F4, LEN(WBB!F4"&")), ""h:mm AM/PM"")), """"), IFERROR(ARRAYFORMULA(TEXT(FILTER(MBB!F4, LEN(MBB!F4)), ""h:mm AM/PM"")), """"), IFERROR(ARRAYFORMULA(TEXT(FILTER(WLAX!F4, LEN(WLAX!F4)), ""h:mm AM/PM"")), """"), IFERROR(ARRAYFORMULA(TEXT(FILTER(MLAX!F4, LEN(MLAX!F4)), "&"""h:mm AM/PM"")), """"), IFERROR(ARRAYFORMULA(TEXT(FILTER(SOFT!F4, LEN(SOFT!F4)), ""h:mm AM/PM"")), """"), IFERROR(ARRAYFORMULA(TEXT(FILTER(BASE!F4, LEN(BASE!F4)), ""h:mm AM/PM"")), """"), IFERROR(ARRAYFORMULA(TEXT(FILTER(ESPORTS!F4, LEN(ESPORTS!F4)"&"), ""h:mm AM/PM"")), """") ) "),"") | J4: =IFERROR(__xludf.DUMMYFUNCTION("IFERROR( TEXTJOIN( CHAR(10) & CHAR(10), TRUE, FILTER( FLATTEN({ WSO!P4; MSO!P4; FH!P4; MGOLF!P4; Football!P4; WVB!P4; XC!P4; SWIMMING!P4; WTEN!P4; TF!P4; WGOLF!P4;"&" WBB!P4; MBB!P4; WLAX!P4; MLAX!P4; SOFT!P4; BASE!P4; ESPORTS!P4 }), (FLATTEN({ WSO!P4; MSO!P4; FH!P4; MGOLF!P4; Football!P4; WVB!P4; XC!P4; "&"SWIMMING!P4; WTEN!P4; TF!P4; WGOLF!P4; WBB!P4; MBB!P4; WLAX!P4; MLAX!P4; SOFT!P4; BASE!P4; ESPORTS!P4 }) <> """") * (FLATTEN({ WSO!P4; MSO!P4; FH!P4; "&" MGOLF!P4; Football!P4; WVB!P4; XC!P4; SWIMMING!P4; WTEN!P4; TF!P4; WGOLF!P4; WBB!P4; MBB!P4; WLAX!P4; MLAX!P4; SOFT!P4; BASE!P4; ESPORTS!P4 }) <> ""S"&"tatus"") ) ), """" ) "),"")
A5: 4 | C5: 46238 | D5: =text(C5,"dddd") -> Tuesday | E5: =TEXTJOIN( CHAR(10) & CHAR(10), TRUE, IFERROR(WSO!E5, ""), IFERROR(MSO!E5, ""), IFERROR(FH!E5, ""), IFERROR(MGOLF!E5, ""), IFERROR(Football!E5, ""), IFERROR(WVB!E5, ""), IFERROR(XC!E5, ""), IFERROR(SWIMMING!E5, ""), IFERROR(WTEN!E5, ""), IFERROR(TF!E5, ""), IFERROR(WGOLF!E5, ""), IFERROR(WBB!E5, ""), IFERROR(MBB!E5, ""), IFERROR(WLAX!E5, ""), IFERROR(MLAX!E5, ""), IFERROR(SOFT!E5, ""), IFERROR(BASE!E5, ""), IFERROR(ESPORTS!E5, "") ) | F5: =IFERROR(__xludf.DUMMYFUNCTION("TEXTJOIN( CHAR(10) & CHAR(10), TRUE, IFERROR(TEXT(FILTER(WSO!F5, LEN(WSO!F5)), ""h:mm AM/PM""), """"), IFERROR(TEXT(FILTER(MSO!F5, LEN(MSO!F5)), ""h:mm AM/PM""), """"), IFERROR(TEXT(FILTER(FH!F5, LEN(FH!F5)), ""h:mm AM/PM""), """"), IFERROR(TE"&"XT(FILTER(MGOLF!F5, LEN(MGOLF!F5)), ""h:mm AM/PM""), """"), IFERROR(TEXT(FILTER(Football!F5, LEN(Football!F5)), ""h:mm AM/PM""), """"), IFERROR(TEXT(FILTER(WVB!F5, LEN(WVB!F5)), ""h:mm AM/PM""), """"), IFERROR(TEXT(FILTER(XC!F5, LEN(XC!F5)), ""h:mm "&"AM/PM""), """"), IFERROR(TEXT(FILTER(SWIMMING!F5, LEN(SWIMMING!F5)), ""h:mm AM/PM""), """"), IFERROR(TEXT(FILTER(WTEN!F5, LEN(WTEN!F5)), ""h:mm AM/PM""), """"), IFERROR(TEXT(FILTER(TF!F5, LEN(TF!F5)), ""h:mm AM/PM""), """"), IFERROR(TEXT(FILTER(WG"&"OLF!F5, LEN(WGOLF!F5)), ""h:mm AM/PM""), """"), IFERROR(TEXT(FILTER(WBB!F5, LEN(WBB!F5)), ""h:mm AM/PM""), """"), IFERROR(TEXT(FILTER(MBB!F5, LEN(MBB!F5)), ""h:mm AM/PM""), """"), IFERROR(TEXT(FILTER(WLAX!F5, LEN(WLAX!F5)), ""h:mm AM/PM""), """"), "&" IFERROR(TEXT(FILTER(MLAX!F5, LEN(MLAX!F5)), ""h:mm AM/PM""), """"), IFERROR(TEXT(FILTER(SOFT!F5, LEN(SOFT!F5)), ""h:mm AM/PM""), """"), IFERROR(TEXT(FILTER(BASE!F5, LEN(BASE!F5)), ""h:mm AM/PM""), """"), IFERROR(TEXT(FILTER(ESPORTS!F5, LEN(ESPORTS!"&"F5)), ""h:mm AM/PM""), """") ) "),"") | G5: =IFERROR(__xludf.DUMMYFUNCTION("TEXTJOIN( CHAR(10) & CHAR(10), TRUE, IFERROR(FILTER(WSO!G5, LEN(WSO!G5)), """"), IFERROR(FILTER(MSO!G5, LEN(MSO!G5)), """"), IFERROR(FILTER(FH!G5, LEN(FH!G5)), """"), IFERROR(FILTER(MGOLF!G5, LEN(MGOLF!G5)), """"), IFERROR(FILTER(Football!G5"&", LEN(Football!G5)), """"), IFERROR(FILTER(WVB!G5, LEN(WVB!G5)), """"), IFERROR(FILTER(XC!G5, LEN(XC!G5)), """"), IFERROR(FILTER(SWIMMING!G5, LEN(SWIMMING!G5)), """"), IFERROR(FILTER(WTEN!G5, LEN(WTEN!G5)), """"), IFERROR(FILTER(TF!G5, LEN(TF!G5"&")), """"), IFERROR(FILTER(WGOLF!G5:G1000, LEN(WGOLF!G5)), """"), IFERROR(FILTER(WBB!G5, LEN(WBB!G5)), """"), IFERROR(FILTER(MBB!G5, LEN(MBB!G5)), """"), IFERROR(FILTER(WLAX!G5, LEN(WLAX!G5)), """"), IFERROR(FILTER(MLAX!G5, LEN(MLAX!G5)), """"), "&" IFERROR(FILTER(SOFT!G5, LEN(SOFT!G5)), """"), IFERROR(FILTER(BASE!G5, LEN(BASE!G5)), """"), IFERROR(FILTER(ESPORTS!G5, LEN(ESPORTS!G5)), """") ) "),"") | H5: =IFERROR(__xludf.DUMMYFUNCTION("TEXTJOIN( CHAR(10) & CHAR(10), TRUE, IFERROR(FILTER(WSO!H5, LEN(WSO!H5)), """"), IFERROR(FILTER(MSO!H5, LEN(MSO!H5)), """"), IFERROR(FILTER(FH!H5, LEN(FH!H5)), """"), IFERROR(FILTER(MGOLF!H5, LEN(MGOLF!H5)), """"), IFERROR(FILTER(Football!H5"&", LEN(Football!H5)), """"), IFERROR(FILTER(WVB!H5, LEN(WVB!H5)), """"), IFERROR(FILTER(XC!H5, LEN(XC!H5)), """"), IFERROR(FILTER(SWIMMING!H5, LEN(SWIMMING!H5)), """"), IFERROR(FILTER(WTEN!H5, LEN(WTEN!H5)), """"), IFERROR(FILTER(TF!H5, LEN(TF!H5"&")), """"), IFERROR(FILTER(WGOLF!H5, LEN(WGOLF!H5)), """"), IFERROR(FILTER(WBB!H5, LEN(WBB!H5)), """"), IFERROR(FILTER(MBB!H5, LEN(MBB!H5)), """"), IFERROR(FILTER(WLAX!H5, LEN(WLAX!H5)), """"), IFERROR(FILTER(MLAX!H5, LEN(MLAX!H5)), """"), IFER"&"ROR(FILTER(SOFT!H5, LEN(SOFT!H5)), """"), IFERROR(FILTER(BASE!H5, LEN(BASE!H5)), """"), IFERROR(FILTER(ESPORTS!H5, LEN(ESPORTS!H5)), """") ) "),"") | I5: =IFERROR(__xludf.DUMMYFUNCTION("TEXTJOIN( CHAR(10) & CHAR(10), TRUE, IFERROR(ARRAYFORMULA(TEXT(FILTER(WSO!F5, LEN(WSO!F5)), ""h:mm AM/PM"")), """"), IFERROR(ARRAYFORMULA(TEXT(FILTER(MSO!F5, LEN(MSO!F5)), ""h:mm AM/PM"")), """"), IFERROR(ARRAYFORMULA(TEXT(FILTER(FH!F5, LEN(FH!F"&"5)), ""h:mm AM/PM"")), """"), IFERROR(ARRAYFORMULA(TEXT(FILTER(MGOLF!F5, LEN(MGOLF!F5)), ""h:mm AM/PM"")), """"), IFERROR(ARRAYFORMULA(TEXT(FILTER(Football!F5, LEN(Football!F5)), ""h:mm AM/PM"")), """"), IFERROR(ARRAYFORMULA(TEXT(FILTER(WVB!F5, LEN("&"WVB!F5)), ""h:mm AM/PM"")), """"), IFERROR(ARRAYFORMULA(TEXT(FILTER(XC!F5, LEN(XC!F5)), ""h:mm AM/PM"")), """"), IFERROR(ARRAYFORMULA(TEXT(FILTER(SWIMMING!F5, LEN(SWIMMING!F5)), ""h:mm AM/PM"")), """"), IFERROR(ARRAYFORMULA(TEXT(FILTER(WTEN!F5, LEN("&"WTEN!F5)), ""h:mm AM/PM"")), """"), IFERROR(ARRAYFORMULA(TEXT(FILTER(TF!F5, LEN(TF!F5)), ""h:mm AM/PM"")), """"), IFERROR(ARRAYFORMULA(TEXT(FILTER(WGOLF!F5, LEN(WGOLF!F5)), ""h:mm AM/PM"")), """"), IFERROR(ARRAYFORMULA(TEXT(FILTER(WBB!F5, LEN(WBB!F5"&")), ""h:mm AM/PM"")), """"), IFERROR(ARRAYFORMULA(TEXT(FILTER(MBB!F5, LEN(MBB!F5)), ""h:mm AM/PM"")), """"), IFERROR(ARRAYFORMULA(TEXT(FILTER(WLAX!F5, LEN(WLAX!F5)), ""h:mm AM/PM"")), """"), IFERROR(ARRAYFORMULA(TEXT(FILTER(MLAX!F5, LEN(MLAX!F5)), "&"""h:mm AM/PM"")), """"), IFERROR(ARRAYFORMULA(TEXT(FILTER(SOFT!F5, LEN(SOFT!F5)), ""h:mm AM/PM"")), """"), IFERROR(ARRAYFORMULA(TEXT(FILTER(BASE!F5, LEN(BASE!F5)), ""h:mm AM/PM"")), """"), IFERROR(ARRAYFORMULA(TEXT(FILTER(ESPORTS!F5, LEN(ESPORTS!F5)"&"), ""h:mm AM/PM"")), """") ) "),"") | J5: =IFERROR(__xludf.DUMMYFUNCTION("IFERROR( TEXTJOIN( CHAR(10) & CHAR(10), TRUE, FILTER( FLATTEN({ WSO!P5; MSO!P5; FH!P5; MGOLF!P5; Football!P5; WVB!P5; XC!P5; SWIMMING!P5; WTEN!P5; TF!P5; WGOLF!P5;"&" WBB!P5; MBB!P5; WLAX!P5; MLAX!P5; SOFT!P5; BASE!P5; ESPORTS!P5 }), (FLATTEN({ WSO!P5; MSO!P5; FH!P5; MGOLF!P5; Football!P5; WVB!P5; XC!P5; "&"SWIMMING!P5; WTEN!P5; TF!P5; WGOLF!P5; WBB!P5; MBB!P5; WLAX!P5; MLAX!P5; SOFT!P5; BASE!P5; ESPORTS!P5 }) <> """") * (FLATTEN({ WSO!P5; MSO!P5; FH!P5; "&" MGOLF!P5; Football!P5; WVB!P5; XC!P5; SWIMMING!P5; WTEN!P5; TF!P5; WGOLF!P5; WBB!P5; MBB!P5; WLAX!P5; MLAX!P5; SOFT!P5; BASE!P5; ESPORTS!P5 }) <> ""S"&"tatus"") ) ), """" ) "),"")
A6: 5 | C6: 46239 | D6: =text(C6,"dddd") -> Wednesday | E6: =TEXTJOIN( CHAR(10) & CHAR(10), TRUE, IFERROR(WSO!E6, ""), IFERROR(MSO!E6, ""), IFERROR(FH!E6, ""), IFERROR(MGOLF!E6, ""), IFERROR(Football!E6, ""), IFERROR(WVB!E6, ""), IFERROR(XC!E6, ""), IFERROR(SWIMMING!E6, ""), IFERROR(WTEN!E6, ""), IFERROR(TF!E6, ""), IFERROR(WGOLF!E6, ""), IFERROR(WBB!E6, ""), IFERROR(MBB!E6, ""), IFERROR(WLAX!E6, ""), IFERROR(MLAX!E6, ""), IFERROR(SOFT!E6, ""), IFERROR(BASE!E6, ""), IFERROR(ESPORTS!E6, "") ) | F6: =IFERROR(__xludf.DUMMYFUNCTION("TEXTJOIN( CHAR(10) & CHAR(10), TRUE, IFERROR(TEXT(FILTER(WSO!F6, LEN(WSO!F6)), ""h:mm AM/PM""), """"), IFERROR(TEXT(FILTER(MSO!F6, LEN(MSO!F6)), ""h:mm AM/PM""), """"), IFERROR(TEXT(FILTER(FH!F6, LEN(FH!F6)), ""h:mm AM/PM""), """"), IFERROR(TE"&"XT(FILTER(MGOLF!F6, LEN(MGOLF!F6)), ""h:mm AM/PM""), """"), IFERROR(TEXT(FILTER(Football!F6, LEN(Football!F6)), ""h:mm AM/PM""), """"), IFERROR(TEXT(FILTER(WVB!F6, LEN(WVB!F6)), ""h:mm AM/PM""), """"), IFERROR(TEXT(FILTER(XC!F6, LEN(XC!F6)), ""h:mm "&"AM/PM""), """"), IFERROR(TEXT(FILTER(SWIMMING!F6, LEN(SWIMMING!F6)), ""h:mm AM/PM""), """"), IFERROR(TEXT(FILTER(WTEN!F6, LEN(WTEN!F6)), ""h:mm AM/PM""), """"), IFERROR(TEXT(FILTER(TF!F6, LEN(TF!F6)), ""h:mm AM/PM""), """"), IFERROR(TEXT(FILTER(WG"&"OLF!F6, LEN(WGOLF!F6)), ""h:mm AM/PM""), """"), IFERROR(TEXT(FILTER(WBB!F6, LEN(WBB!F6)), ""h:mm AM/PM""), """"), IFERROR(TEXT(FILTER(MBB!F6, LEN(MBB!F6)), ""h:mm AM/PM""), """"), IFERROR(TEXT(FILTER(WLAX!F6, LEN(WLAX!F6)), ""h:mm AM/PM""), """"), "&" IFERROR(TEXT(FILTER(MLAX!F6, LEN(MLAX!F6)), ""h:mm AM/PM""), """"), IFERROR(TEXT(FILTER(SOFT!F6, LEN(SOFT!F6)), ""h:mm AM/PM""), """"), IFERROR(TEXT(FILTER(BASE!F6, LEN(BASE!F6)), ""h:mm AM/PM""), """"), IFERROR(TEXT(FILTER(ESPORTS!F6, LEN(ESPORTS!"&"F6)), ""h:mm AM/PM""), """") ) "),"") | G6: =IFERROR(__xludf.DUMMYFUNCTION("TEXTJOIN( CHAR(10) & CHAR(10), TRUE, IFERROR(FILTER(WSO!G6, LEN(WSO!G6)), """"), IFERROR(FILTER(MSO!G6, LEN(MSO!G6)), """"), IFERROR(FILTER(FH!G6, LEN(FH!G6)), """"), IFERROR(FILTER(MGOLF!G6, LEN(MGOLF!G6)), """"), IFERROR(FILTER(Football!G6"&", LEN(Football!G6)), """"), IFERROR(FILTER(WVB!G6, LEN(WVB!G6)), """"), IFERROR(FILTER(XC!G6, LEN(XC!G6)), """"), IFERROR(FILTER(SWIMMING!G6, LEN(SWIMMING!G6)), """"), IFERROR(FILTER(WTEN!G6, LEN(WTEN!G6)), """"), IFERROR(FILTER(TF!G6, LEN(TF!G6"&")), """"), IFERROR(FILTER(WGOLF!G6:G1000, LEN(WGOLF!G6)), """"), IFERROR(FILTER(WBB!G6, LEN(WBB!G6)), """"), IFERROR(FILTER(MBB!G6, LEN(MBB!G6)), """"), IFERROR(FILTER(WLAX!G6, LEN(WLAX!G6)), """"), IFERROR(FILTER(MLAX!G6, LEN(MLAX!G6)), """"), "&" IFERROR(FILTER(SOFT!G6, LEN(SOFT!G6)), """"), IFERROR(FILTER(BASE!G6, LEN(BASE!G6)), """"), IFERROR(FILTER(ESPORTS!G6, LEN(ESPORTS!G6)), """") ) "),"") | H6: =IFERROR(__xludf.DUMMYFUNCTION("TEXTJOIN( CHAR(10) & CHAR(10), TRUE, IFERROR(FILTER(WSO!H6, LEN(WSO!H6)), """"), IFERROR(FILTER(MSO!H6, LEN(MSO!H6)), """"), IFERROR(FILTER(FH!H6, LEN(FH!H6)), """"), IFERROR(FILTER(MGOLF!H6, LEN(MGOLF!H6)), """"), IFERROR(FILTER(Football!H6"&", LEN(Football!H6)), """"), IFERROR(FILTER(WVB!H6, LEN(WVB!H6)), """"), IFERROR(FILTER(XC!H6, LEN(XC!H6)), """"), IFERROR(FILTER(SWIMMING!H6, LEN(SWIMMING!H6)), """"), IFERROR(FILTER(WTEN!H6, LEN(WTEN!H6)), """"), IFERROR(FILTER(TF!H6, LEN(TF!H6"&")), """"), IFERROR(FILTER(WGOLF!H6, LEN(WGOLF!H6)), """"), IFERROR(FILTER(WBB!H6, LEN(WBB!H6)), """"), IFERROR(FILTER(MBB!H6, LEN(MBB!H6)), """"), IFERROR(FILTER(WLAX!H6, LEN(WLAX!H6)), """"), IFERROR(FILTER(MLAX!H6, LEN(MLAX!H6)), """"), IFER"&"ROR(FILTER(SOFT!H6, LEN(SOFT!H6)), """"), IFERROR(FILTER(BASE!H6, LEN(BASE!H6)), """"), IFERROR(FILTER(ESPORTS!H6, LEN(ESPORTS!H6)), """") ) "),"") | I6: =IFERROR(__xludf.DUMMYFUNCTION("TEXTJOIN( CHAR(10) & CHAR(10), TRUE, IFERROR(ARRAYFORMULA(TEXT(FILTER(WSO!F6, LEN(WSO!F6)), ""h:mm AM/PM"")), """"), IFERROR(ARRAYFORMULA(TEXT(FILTER(MSO!F6, LEN(MSO!F6)), ""h:mm AM/PM"")), """"), IFERROR(ARRAYFORMULA(TEXT(FILTER(FH!F6, LEN(FH!F"&"6)), ""h:mm AM/PM"")), """"), IFERROR(ARRAYFORMULA(TEXT(FILTER(MGOLF!F6, LEN(MGOLF!F6)), ""h:mm AM/PM"")), """"), IFERROR(ARRAYFORMULA(TEXT(FILTER(Football!F6, LEN(Football!F6)), ""h:mm AM/PM"")), """"), IFERROR(ARRAYFORMULA(TEXT(FILTER(WVB!F6, LEN("&"WVB!F6)), ""h:mm AM/PM"")), """"), IFERROR(ARRAYFORMULA(TEXT(FILTER(XC!F6, LEN(XC!F6)), ""h:mm AM/PM"")), """"), IFERROR(ARRAYFORMULA(TEXT(FILTER(SWIMMING!F6, LEN(SWIMMING!F6)), ""h:mm AM/PM"")), """"), IFERROR(ARRAYFORMULA(TEXT(FILTER(WTEN!F6, LEN("&"WTEN!F6)), ""h:mm AM/PM"")), """"), IFERROR(ARRAYFORMULA(TEXT(FILTER(TF!F6, LEN(TF!F6)), ""h:mm AM/PM"")), """"), IFERROR(ARRAYFORMULA(TEXT(FILTER(WGOLF!F6, LEN(WGOLF!F6)), ""h:mm AM/PM"")), """"), IFERROR(ARRAYFORMULA(TEXT(FILTER(WBB!F6, LEN(WBB!F6"&")), ""h:mm AM/PM"")), """"), IFERROR(ARRAYFORMULA(TEXT(FILTER(MBB!F6, LEN(MBB!F6)), ""h:mm AM/PM"")), """"), IFERROR(ARRAYFORMULA(TEXT(FILTER(WLAX!F6, LEN(WLAX!F6)), ""h:mm AM/PM"")), """"), IFERROR(ARRAYFORMULA(TEXT(FILTER(MLAX!F6, LEN(MLAX!F6)), "&"""h:mm AM/PM"")), """"), IFERROR(ARRAYFORMULA(TEXT(FILTER(SOFT!F6, LEN(SOFT!F6)), ""h:mm AM/PM"")), """"), IFERROR(ARRAYFORMULA(TEXT(FILTER(BASE!F6, LEN(BASE!F6)), ""h:mm AM/PM"")), """"), IFERROR(ARRAYFORMULA(TEXT(FILTER(ESPORTS!F6, LEN(ESPORTS!F6)"&"), ""h:mm AM/PM"")), """") ) "),"") | J6: =IFERROR(__xludf.DUMMYFUNCTION("IFERROR( TEXTJOIN( CHAR(10) & CHAR(10), TRUE, FILTER( FLATTEN({ WSO!P6; MSO!P6; FH!P6; MGOLF!P6; Football!P6; WVB!P6; XC!P6; SWIMMING!P6; WTEN!P6; TF!P6; WGOLF!P6;"&" WBB!P6; MBB!P6; WLAX!P6; MLAX!P6; SOFT!P6; BASE!P6; ESPORTS!P6 }), (FLATTEN({ WSO!P6; MSO!P6; FH!P6; MGOLF!P6; Football!P6; WVB!P6; XC!P6; "&"SWIMMING!P6; WTEN!P6; TF!P6; WGOLF!P6; WBB!P6; MBB!P6; WLAX!P6; MLAX!P6; SOFT!P6; BASE!P6; ESPORTS!P6 }) <> """") * (FLATTEN({ WSO!P6; MSO!P6; FH!P6; "&" MGOLF!P6; Football!P6; WVB!P6; XC!P6; SWIMMING!P6; WTEN!P6; TF!P6; WGOLF!P6; WBB!P6; MBB!P6; WLAX!P6; MLAX!P6; SOFT!P6; BASE!P6; ESPORTS!P6 }) <> ""S"&"tatus"") ) ), """" ) "),"")
A7: 6 | C7: 46240 | D7: =text(C7,"dddd") -> Thursday | E7: =TEXTJOIN( CHAR(10) & CHAR(10), TRUE, IFERROR(WSO!E7, ""), IFERROR(MSO!E7, ""), IFERROR(FH!E7, ""), IFERROR(MGOLF!E7, ""), IFERROR(Football!E7, ""), IFERROR(WVB!E7, ""), IFERROR(XC!E7, ""), IFERROR(SWIMMING!E7, ""), IFERROR(WTEN!E7, ""), IFERROR(TF!E7, ""), IFERROR(WGOLF!E7, ""), IFERROR(WBB!E7, ""), IFERROR(MBB!E7, ""), IFERROR(WLAX!E7, ""), IFERROR(MLAX!E7, ""), IFERROR(SOFT!E7, ""), IFERROR(BASE!E7, ""), IFERROR(ESPORTS!E7, "") ) | F7: =IFERROR(__xludf.DUMMYFUNCTION("TEXTJOIN( CHAR(10) & CHAR(10), TRUE, IFERROR(TEXT(FILTER(WSO!F7, LEN(WSO!F7)), ""h:mm AM/PM""), """"), IFERROR(TEXT(FILTER(MSO!F7, LEN(MSO!F7)), ""h:mm AM/PM""), """"), IFERROR(TEXT(FILTER(FH!F7, LEN(FH!F7)), ""h:mm AM/PM""), """"), IFERROR(TE"&"XT(FILTER(MGOLF!F7, LEN(MGOLF!F7)), ""h:mm AM/PM""), """"), IFERROR(TEXT(FILTER(Football!F7, LEN(Football!F7)), ""h:mm AM/PM""), """"), IFERROR(TEXT(FILTER(WVB!F7, LEN(WVB!F7)), ""h:mm AM/PM""), """"), IFERROR(TEXT(FILTER(XC!F7, LEN(XC!F7)), ""h:mm "&"AM/PM""), """"), IFERROR(TEXT(FILTER(SWIMMING!F7, LEN(SWIMMING!F7)), ""h:mm AM/PM""), """"), IFERROR(TEXT(FILTER(WTEN!F7, LEN(WTEN!F7)), ""h:mm AM/PM""), """"), IFERROR(TEXT(FILTER(TF!F7, LEN(TF!F7)), ""h:mm AM/PM""), """"), IFERROR(TEXT(FILTER(WG"&"OLF!F7, LEN(WGOLF!F7)), ""h:mm AM/PM""), """"), IFERROR(TEXT(FILTER(WBB!F7, LEN(WBB!F7)), ""h:mm AM/PM""), """"), IFERROR(TEXT(FILTER(MBB!F7, LEN(MBB!F7)), ""h:mm AM/PM""), """"), IFERROR(TEXT(FILTER(WLAX!F7, LEN(WLAX!F7)), ""h:mm AM/PM""), """"), "&" IFERROR(TEXT(FILTER(MLAX!F7, LEN(MLAX!F7)), ""h:mm AM/PM""), """"), IFERROR(TEXT(FILTER(SOFT!F7, LEN(SOFT!F7)), ""h:mm AM/PM""), """"), IFERROR(TEXT(FILTER(BASE!F7, LEN(BASE!F7)), ""h:mm AM/PM""), """"), IFERROR(TEXT(FILTER(ESPORTS!F7, LEN(ESPORTS!"&"F7)), ""h:mm AM/PM""), """") ) "),"") | G7: =IFERROR(__xludf.DUMMYFUNCTION("TEXTJOIN( CHAR(10) & CHAR(10), TRUE, IFERROR(FILTER(WSO!G7, LEN(WSO!G7)), """"), IFERROR(FILTER(MSO!G7, LEN(MSO!G7)), """"), IFERROR(FILTER(FH!G7, LEN(FH!G7)), """"), IFERROR(FILTER(MGOLF!G7, LEN(MGOLF!G7)), """"), IFERROR(FILTER(Football!G7"&", LEN(Football!G7)), """"), IFERROR(FILTER(WVB!G7, LEN(WVB!G7)), """"), IFERROR(FILTER(XC!G7, LEN(XC!G7)), """"), IFERROR(FILTER(SWIMMING!G7, LEN(SWIMMING!G7)), """"), IFERROR(FILTER(WTEN!G7, LEN(WTEN!G7)), """"), IFERROR(FILTER(TF!G7, LEN(TF!G7"&")), """"), IFERROR(FILTER(WGOLF!G7:G1000, LEN(WGOLF!G7)), """"), IFERROR(FILTER(WBB!G7, LEN(WBB!G7)), """"), IFERROR(FILTER(MBB!G7, LEN(MBB!G7)), """"), IFERROR(FILTER(WLAX!G7, LEN(WLAX!G7)), """"), IFERROR(FILTER(MLAX!G7, LEN(MLAX!G7)), """"), "&" IFERROR(FILTER(SOFT!G7, LEN(SOFT!G7)), """"), IFERROR(FILTER(BASE!G7, LEN(BASE!G7)), """"), IFERROR(FILTER(ESPORTS!G7, LEN(ESPORTS!G7)), """") ) "),"") | H7: =IFERROR(__xludf.DUMMYFUNCTION("TEXTJOIN( CHAR(10) & CHAR(10), TRUE, IFERROR(FILTER(WSO!H7, LEN(WSO!H7)), """"), IFERROR(FILTER(MSO!H7, LEN(MSO!H7)), """"), IFERROR(FILTER(FH!H7, LEN(FH!H7)), """"), IFERROR(FILTER(MGOLF!H7, LEN(MGOLF!H7)), """"), IFERROR(FILTER(Football!H7"&", LEN(Football!H7)), """"), IFERROR(FILTER(WVB!H7, LEN(WVB!H7)), """"), IFERROR(FILTER(XC!H7, LEN(XC!H7)), """"), IFERROR(FILTER(SWIMMING!H7, LEN(SWIMMING!H7)), """"), IFERROR(FILTER(WTEN!H7, LEN(WTEN!H7)), """"), IFERROR(FILTER(TF!H7, LEN(TF!H7"&")), """"), IFERROR(FILTER(WGOLF!H7, LEN(WGOLF!H7)), """"), IFERROR(FILTER(WBB!H7, LEN(WBB!H7)), """"), IFERROR(FILTER(MBB!H7, LEN(MBB!H7)), """"), IFERROR(FILTER(WLAX!H7, LEN(WLAX!H7)), """"), IFERROR(FILTER(MLAX!H7, LEN(MLAX!H7)), """"), IFER"&"ROR(FILTER(SOFT!H7, LEN(SOFT!H7)), """"), IFERROR(FILTER(BASE!H7, LEN(BASE!H7)), """"), IFERROR(FILTER(ESPORTS!H7, LEN(ESPORTS!H7)), """") ) "),"") | I7: =IFERROR(__xludf.DUMMYFUNCTION("TEXTJOIN( CHAR(10) & CHAR(10), TRUE, IFERROR(ARRAYFORMULA(TEXT(FILTER(WSO!F7, LEN(WSO!F7)), ""h:mm AM/PM"")), """"), IFERROR(ARRAYFORMULA(TEXT(FILTER(MSO!F7, LEN(MSO!F7)), ""h:mm AM/PM"")), """"), IFERROR(ARRAYFORMULA(TEXT(FILTER(FH!F7, LEN(FH!F"&"7)), ""h:mm AM/PM"")), """"), IFERROR(ARRAYFORMULA(TEXT(FILTER(MGOLF!F7, LEN(MGOLF!F7)), ""h:mm AM/PM"")), """"), IFERROR(ARRAYFORMULA(TEXT(FILTER(Football!F7, LEN(Football!F7)), ""h:mm AM/PM"")), """"), IFERROR(ARRAYFORMULA(TEXT(FILTER(WVB!F7, LEN("&"WVB!F7)), ""h:mm AM/PM"")), """"), IFERROR(ARRAYFORMULA(TEXT(FILTER(XC!F7, LEN(XC!F7)), ""h:mm AM/PM"")), """"), IFERROR(ARRAYFORMULA(TEXT(FILTER(SWIMMING!F7, LEN(SWIMMING!F7)), ""h:mm AM/PM"")), """"), IFERROR(ARRAYFORMULA(TEXT(FILTER(WTEN!F7, LEN("&"WTEN!F7)), ""h:mm AM/PM"")), """"), IFERROR(ARRAYFORMULA(TEXT(FILTER(TF!F7, LEN(TF!F7)), ""h:mm AM/PM"")), """"), IFERROR(ARRAYFORMULA(TEXT(FILTER(WGOLF!F7, LEN(WGOLF!F7)), ""h:mm AM/PM"")), """"), IFERROR(ARRAYFORMULA(TEXT(FILTER(WBB!F7, LEN(WBB!F7"&")), ""h:mm AM/PM"")), """"), IFERROR(ARRAYFORMULA(TEXT(FILTER(MBB!F7, LEN(MBB!F7)), ""h:mm AM/PM"")), """"), IFERROR(ARRAYFORMULA(TEXT(FILTER(WLAX!F7, LEN(WLAX!F7)), ""h:mm AM/PM"")), """"), IFERROR(ARRAYFORMULA(TEXT(FILTER(MLAX!F7, LEN(MLAX!F7)), "&"""h:mm AM/PM"")), """"), IFERROR(ARRAYFORMULA(TEXT(FILTER(SOFT!F7, LEN(SOFT!F7)), ""h:mm AM/PM"")), """"), IFERROR(ARRAYFORMULA(TEXT(FILTER(BASE!F7, LEN(BASE!F7)), ""h:mm AM/PM"")), """"), IFERROR(ARRAYFORMULA(TEXT(FILTER(ESPORTS!F7, LEN(ESPORTS!F7)"&"), ""h:mm AM/PM"")), """") ) "),"") | J7: =IFERROR(__xludf.DUMMYFUNCTION("IFERROR( TEXTJOIN( CHAR(10) & CHAR(10), TRUE, FILTER( FLATTEN({ WSO!P7; MSO!P7; FH!P7; MGOLF!P7; Football!P7; WVB!P7; XC!P7; SWIMMING!P7; WTEN!P7; TF!P7; WGOLF!P7;"&" WBB!P7; MBB!P7; WLAX!P7; MLAX!P7; SOFT!P7; BASE!P7; ESPORTS!P7 }), (FLATTEN({ WSO!P7; MSO!P7; FH!P7; MGOLF!P7; Football!P7; WVB!P7; XC!P7; "&"SWIMMING!P7; WTEN!P7; TF!P7; WGOLF!P7; WBB!P7; MBB!P7; WLAX!P7; MLAX!P7; SOFT!P7; BASE!P7; ESPORTS!P7 }) <> """") * (FLATTEN({ WSO!P7; MSO!P7; FH!P7; "&" MGOLF!P7; Football!P7; WVB!P7; XC!P7; SWIMMING!P7; WTEN!P7; TF!P7; WGOLF!P7; WBB!P7; MBB!P7; WLAX!P7; MLAX!P7; SOFT!P7; BASE!P7; ESPORTS!P7 }) <> ""S"&"tatus"") ) ), """" ) "),"")
A8: 7 | C8: 46241 | D8: =text(C8,"dddd") -> Friday | E8: =TEXTJOIN( CHAR(10) & CHAR(10), TRUE, IFERROR(WSO!E8, ""), IFERROR(MSO!E8, ""), IFERROR(FH!E8, ""), IFERROR(MGOLF!E8, ""), IFERROR(Football!E8, ""), IFERROR(WVB!E8, ""), IFERROR(XC!E8, ""), IFERROR(SWIMMING!E8, ""), IFERROR(WTEN!E8, ""), IFERROR(TF!E8, ""), IFERROR(WGOLF!E8, ""), IFERROR(WBB!E8, ""), IFERROR(MBB!E8, ""), IFERROR(WLAX!E8, ""), IFERROR(MLAX!E8, ""), IFERROR(SOFT!E8, ""), IFERROR(BASE!E8, ""), IFERROR(ESPORTS!E8, "") ) | F8: =IFERROR(__xludf.DUMMYFUNCTION("TEXTJOIN( CHAR(10) & CHAR(10), TRUE, IFERROR(TEXT(FILTER(WSO!F8, LEN(WSO!F8)), ""h:mm AM/PM""), """"), IFERROR(TEXT(FILTER(MSO!F8, LEN(MSO!F8)), ""h:mm AM/PM""), """"), IFERROR(TEXT(FILTER(FH!F8, LEN(FH!F8)), ""h:mm AM/PM""), """"), IFERROR(TE"&"XT(FILTER(MGOLF!F8, LEN(MGOLF!F8)), ""h:mm AM/PM""), """"), IFERROR(TEXT(FILTER(Football!F8, LEN(Football!F8)), ""h:mm AM/PM""), """"), IFERROR(TEXT(FILTER(WVB!F8, LEN(WVB!F8)), ""h:mm AM/PM""), """"), IFERROR(TEXT(FILTER(XC!F8, LEN(XC!F8)), ""h:mm "&"AM/PM""), """"), IFERROR(TEXT(FILTER(SWIMMING!F8, LEN(SWIMMING!F8)), ""h:mm AM/PM""), """"), IFERROR(TEXT(FILTER(WTEN!F8, LEN(WTEN!F8)), ""h:mm AM/PM""), """"), IFERROR(TEXT(FILTER(TF!F8, LEN(TF!F8)), ""h:mm AM/PM""), """"), IFERROR(TEXT(FILTER(WG"&"OLF!F8, LEN(WGOLF!F8)), ""h:mm AM/PM""), """"), IFERROR(TEXT(FILTER(WBB!F8, LEN(WBB!F8)), ""h:mm AM/PM""), """"), IFERROR(TEXT(FILTER(MBB!F8, LEN(MBB!F8)), ""h:mm AM/PM""), """"), IFERROR(TEXT(FILTER(WLAX!F8, LEN(WLAX!F8)), ""h:mm AM/PM""), """"), "&" IFERROR(TEXT(FILTER(MLAX!F8, LEN(MLAX!F8)), ""h:mm AM/PM""), """"), IFERROR(TEXT(FILTER(SOFT!F8, LEN(SOFT!F8)), ""h:mm AM/PM""), """"), IFERROR(TEXT(FILTER(BASE!F8, LEN(BASE!F8)), ""h:mm AM/PM""), """"), IFERROR(TEXT(FILTER(ESPORTS!F8, LEN(ESPORTS!"&"F8)), ""h:mm AM/PM""), """") ) "),"") | G8: =IFERROR(__xludf.DUMMYFUNCTION("TEXTJOIN( CHAR(10) & CHAR(10), TRUE, IFERROR(FILTER(WSO!G8, LEN(WSO!G8)), """"), IFERROR(FILTER(MSO!G8, LEN(MSO!G8)), """"), IFERROR(FILTER(FH!G8, LEN(FH!G8)), """"), IFERROR(FILTER(MGOLF!G8, LEN(MGOLF!G8)), """"), IFERROR(FILTER(Football!G8"&", LEN(Football!G8)), """"), IFERROR(FILTER(WVB!G8, LEN(WVB!G8)), """"), IFERROR(FILTER(XC!G8, LEN(XC!G8)), """"), IFERROR(FILTER(SWIMMING!G8, LEN(SWIMMING!G8)), """"), IFERROR(FILTER(WTEN!G8, LEN(WTEN!G8)), """"), IFERROR(FILTER(TF!G8, LEN(TF!G8"&")), """"), IFERROR(FILTER(WGOLF!G8:G1000, LEN(WGOLF!G8)), """"), IFERROR(FILTER(WBB!G8, LEN(WBB!G8)), """"), IFERROR(FILTER(MBB!G8, LEN(MBB!G8)), """"), IFERROR(FILTER(WLAX!G8, LEN(WLAX!G8)), """"), IFERROR(FILTER(MLAX!G8, LEN(MLAX!G8)), """"), "&" IFERROR(FILTER(SOFT!G8, LEN(SOFT!G8)), """"), IFERROR(FILTER(BASE!G8, LEN(BASE!G8)), """"), IFERROR(FILTER(ESPORTS!G8, LEN(ESPORTS!G8)), """") ) "),"") | H8: =IFERROR(__xludf.DUMMYFUNCTION("TEXTJOIN( CHAR(10) & CHAR(10), TRUE, IFERROR(FILTER(WSO!H8, LEN(WSO!H8)), """"), IFERROR(FILTER(MSO!H8, LEN(MSO!H8)), """"), IFERROR(FILTER(FH!H8, LEN(FH!H8)), """"), IFERROR(FILTER(MGOLF!H8, LEN(MGOLF!H8)), """"), IFERROR(FILTER(Football!H8"&", LEN(Football!H8)), """"), IFERROR(FILTER(WVB!H8, LEN(WVB!H8)), """"), IFERROR(FILTER(XC!H8, LEN(XC!H8)), """"), IFERROR(FILTER(SWIMMING!H8, LEN(SWIMMING!H8)), """"), IFERROR(FILTER(WTEN!H8, LEN(WTEN!H8)), """"), IFERROR(FILTER(TF!H8, LEN(TF!H8"&")), """"), IFERROR(FILTER(WGOLF!H8, LEN(WGOLF!H8)), """"), IFERROR(FILTER(WBB!H8, LEN(WBB!H8)), """"), IFERROR(FILTER(MBB!H8, LEN(MBB!H8)), """"), IFERROR(FILTER(WLAX!H8, LEN(WLAX!H8)), """"), IFERROR(FILTER(MLAX!H8, LEN(MLAX!H8)), """"), IFER"&"ROR(FILTER(SOFT!H8, LEN(SOFT!H8)), """"), IFERROR(FILTER(BASE!H8, LEN(BASE!H8)), """"), IFERROR(FILTER(ESPORTS!H8, LEN(ESPORTS!H8)), """") ) "),"") | I8: =IFERROR(__xludf.DUMMYFUNCTION("TEXTJOIN( CHAR(10) & CHAR(10), TRUE, IFERROR(ARRAYFORMULA(TEXT(FILTER(WSO!F8, LEN(WSO!F8)), ""h:mm AM/PM"")), """"), IFERROR(ARRAYFORMULA(TEXT(FILTER(MSO!F8, LEN(MSO!F8)), ""h:mm AM/PM"")), """"), IFERROR(ARRAYFORMULA(TEXT(FILTER(FH!F8, LEN(FH!F"&"8)), ""h:mm AM/PM"")), """"), IFERROR(ARRAYFORMULA(TEXT(FILTER(MGOLF!F8, LEN(MGOLF!F8)), ""h:mm AM/PM"")), """"), IFERROR(ARRAYFORMULA(TEXT(FILTER(Football!F8, LEN(Football!F8)), ""h:mm AM/PM"")), """"), IFERROR(ARRAYFORMULA(TEXT(FILTER(WVB!F8, LEN("&"WVB!F8)), ""h:mm AM/PM"")), """"), IFERROR(ARRAYFORMULA(TEXT(FILTER(XC!F8, LEN(XC!F8)), ""h:mm AM/PM"")), """"), IFERROR(ARRAYFORMULA(TEXT(FILTER(SWIMMING!F8, LEN(SWIMMING!F8)), ""h:mm AM/PM"")), """"), IFERROR(ARRAYFORMULA(TEXT(FILTER(WTEN!F8, LEN("&"WTEN!F8)), ""h:mm AM/PM"")), """"), IFERROR(ARRAYFORMULA(TEXT(FILTER(TF!F8, LEN(TF!F8)), ""h:mm AM/PM"")), """"), IFERROR(ARRAYFORMULA(TEXT(FILTER(WGOLF!F8, LEN(WGOLF!F8)), ""h:mm AM/PM"")), """"), IFERROR(ARRAYFORMULA(TEXT(FILTER(WBB!F8, LEN(WBB!F8"&")), ""h:mm AM/PM"")), """"), IFERROR(ARRAYFORMULA(TEXT(FILTER(MBB!F8, LEN(MBB!F8)), ""h:mm AM/PM"")), """"), IFERROR(ARRAYFORMULA(TEXT(FILTER(WLAX!F8, LEN(WLAX!F8)), ""h:mm AM/PM"")), """"), IFERROR(ARRAYFORMULA(TEXT(FILTER(MLAX!F8, LEN(MLAX!F8)), "&"""h:mm AM/PM"")), """"), IFERROR(ARRAYFORMULA(TEXT(FILTER(SOFT!F8, LEN(SOFT!F8)), ""h:mm AM/PM"")), """"), IFERROR(ARRAYFORMULA(TEXT(FILTER(BASE!F8, LEN(BASE!F8)), ""h:mm AM/PM"")), """"), IFERROR(ARRAYFORMULA(TEXT(FILTER(ESPORTS!F8, LEN(ESPORTS!F8)"&"), ""h:mm AM/PM"")), """") ) "),"") | J8: =IFERROR(__xludf.DUMMYFUNCTION("IFERROR( TEXTJOIN( CHAR(10) & CHAR(10), TRUE, FILTER( FLATTEN({ WSO!P8; MSO!P8; FH!P8; MGOLF!P8; Football!P8; WVB!P8; XC!P8; SWIMMING!P8; WTEN!P8; TF!P8; WGOLF!P8;"&" WBB!P8; MBB!P8; WLAX!P8; MLAX!P8; SOFT!P8; BASE!P8; ESPORTS!P8 }), (FLATTEN({ WSO!P8; MSO!P8; FH!P8; MGOLF!P8; Football!P8; WVB!P8; XC!P8; "&"SWIMMING!P8; WTEN!P8; TF!P8; WGOLF!P8; WBB!P8; MBB!P8; WLAX!P8; MLAX!P8; SOFT!P8; BASE!P8; ESPORTS!P8 }) <> """") * (FLATTEN({ WSO!P8; MSO!P8; FH!P8; "&" MGOLF!P8; Football!P8; WVB!P8; XC!P8; SWIMMING!P8; WTEN!P8; TF!P8; WGOLF!P8; WBB!P8; MBB!P8; WLAX!P8; MLAX!P8; SOFT!P8; BASE!P8; ESPORTS!P8 }) <> ""S"&"tatus"") ) ), """" ) "),"")
A9: 8 | C9: 46242 | D9: =text(C9,"dddd") -> Saturday | E9: =TEXTJOIN( CHAR(10) & CHAR(10), TRUE, IFERROR(WSO!E9, ""), IFERROR(MSO!E9, ""), IFERROR(FH!E9, ""), IFERROR(MGOLF!E9, ""), IFERROR(Football!E9, ""), IFERROR(WVB!E9, ""), IFERROR(XC!E9, ""), IFERROR(SWIMMING!E9, ""), IFERROR(WTEN!E9, ""), IFERROR(TF!E9, ""), IFERROR(WGOLF!E9, ""), IFERROR(WBB!E9, ""), IFERROR(MBB!E9, ""), IFERROR(WLAX!E9, ""), IFERROR(MLAX!E9, ""), IFERROR(SOFT!E9, ""), IFERROR(BASE!E9, ""), IFERROR(ESPORTS!E9, "") ) | F9: =IFERROR(__xludf.DUMMYFUNCTION("TEXTJOIN( CHAR(10) & CHAR(10), TRUE, IFERROR(TEXT(FILTER(WSO!F9, LEN(WSO!F9)), ""h:mm AM/PM""), """"), IFERROR(TEXT(FILTER(MSO!F9, LEN(MSO!F9)), ""h:mm AM/PM""), """"), IFERROR(TEXT(FILTER(FH!F9, LEN(FH!F9)), ""h:mm AM/PM""), """"), IFERROR(TE"&"XT(FILTER(MGOLF!F9, LEN(MGOLF!F9)), ""h:mm AM/PM""), """"), IFERROR(TEXT(FILTER(Football!F9, LEN(Football!F9)), ""h:mm AM/PM""), """"), IFERROR(TEXT(FILTER(WVB!F9, LEN(WVB!F9)), ""h:mm AM/PM""), """"), IFERROR(TEXT(FILTER(XC!F9, LEN(XC!F9)), ""h:mm "&"AM/PM""), """"), IFERROR(TEXT(FILTER(SWIMMING!F9, LEN(SWIMMING!F9)), ""h:mm AM/PM""), """"), IFERROR(TEXT(FILTER(WTEN!F9, LEN(WTEN!F9)), ""h:mm AM/PM""), """"), IFERROR(TEXT(FILTER(TF!F9, LEN(TF!F9)), ""h:mm AM/PM""), """"), IFERROR(TEXT(FILTER(WG"&"OLF!F9, LEN(WGOLF!F9)), ""h:mm AM/PM""), """"), IFERROR(TEXT(FILTER(WBB!F9, LEN(WBB!F9)), ""h:mm AM/PM""), """"), IFERROR(TEXT(FILTER(MBB!F9, LEN(MBB!F9)), ""h:mm AM/PM""), """"), IFERROR(TEXT(FILTER(WLAX!F9, LEN(WLAX!F9)), ""h:mm AM/PM""), """"), "&" IFERROR(TEXT(FILTER(MLAX!F9, LEN(MLAX!F9)), ""h:mm AM/PM""), """"), IFERROR(TEXT(FILTER(SOFT!F9, LEN(SOFT!F9)), ""h:mm AM/PM""), """"), IFERROR(TEXT(FILTER(BASE!F9, LEN(BASE!F9)), ""h:mm AM/PM""), """"), IFERROR(TEXT(FILTER(ESPORTS!F9, LEN(ESPORTS!"&"F9)), ""h:mm AM/PM""), """") ) "),"") | G9: =IFERROR(__xludf.DUMMYFUNCTION("TEXTJOIN( CHAR(10) & CHAR(10), TRUE, IFERROR(FILTER(WSO!G9, LEN(WSO!G9)), """"), IFERROR(FILTER(MSO!G9, LEN(MSO!G9)), """"), IFERROR(FILTER(FH!G9, LEN(FH!G9)), """"), IFERROR(FILTER(MGOLF!G9, LEN(MGOLF!G9)), """"), IFERROR(FILTER(Football!G9"&", LEN(Football!G9)), """"), IFERROR(FILTER(WVB!G9, LEN(WVB!G9)), """"), IFERROR(FILTER(XC!G9, LEN(XC!G9)), """"), IFERROR(FILTER(SWIMMING!G9, LEN(SWIMMING!G9)), """"), IFERROR(FILTER(WTEN!G9, LEN(WTEN!G9)), """"), IFERROR(FILTER(TF!G9, LEN(TF!G9"&")), """"), IFERROR(FILTER(WGOLF!G9:G1000, LEN(WGOLF!G9)), """"), IFERROR(FILTER(WBB!G9, LEN(WBB!G9)), """"), IFERROR(FILTER(MBB!G9, LEN(MBB!G9)), """"), IFERROR(FILTER(WLAX!G9, LEN(WLAX!G9)), """"), IFERROR(FILTER(MLAX!G9, LEN(MLAX!G9)), """"), "&" IFERROR(FILTER(SOFT!G9, LEN(SOFT!G9)), """"), IFERROR(FILTER(BASE!G9, LEN(BASE!G9)), """"), IFERROR(FILTER(ESPORTS!G9, LEN(ESPORTS!G9)), """") ) "),"") | H9: =IFERROR(__xludf.DUMMYFUNCTION("TEXTJOIN( CHAR(10) & CHAR(10), TRUE, IFERROR(FILTER(WSO!H9, LEN(WSO!H9)), """"), IFERROR(FILTER(MSO!H9, LEN(MSO!H9)), """"), IFERROR(FILTER(FH!H9, LEN(FH!H9)), """"), IFERROR(FILTER(MGOLF!H9, LEN(MGOLF!H9)), """"), IFERROR(FILTER(Football!H9"&", LEN(Football!H9)), """"), IFERROR(FILTER(WVB!H9, LEN(WVB!H9)), """"), IFERROR(FILTER(XC!H9, LEN(XC!H9)), """"), IFERROR(FILTER(SWIMMING!H9, LEN(SWIMMING!H9)), """"), IFERROR(FILTER(WTEN!H9, LEN(WTEN!H9)), """"), IFERROR(FILTER(TF!H9, LEN(TF!H9"&")), """"), IFERROR(FILTER(WGOLF!H9, LEN(WGOLF!H9)), """"), IFERROR(FILTER(WBB!H9, LEN(WBB!H9)), """"), IFERROR(FILTER(MBB!H9, LEN(MBB!H9)), """"), IFERROR(FILTER(WLAX!H9, LEN(WLAX!H9)), """"), IFERROR(FILTER(MLAX!H9, LEN(MLAX!H9)), """"), IFER"&"ROR(FILTER(SOFT!H9, LEN(SOFT!H9)), """"), IFERROR(FILTER(BASE!H9, LEN(BASE!H9)), """"), IFERROR(FILTER(ESPORTS!H9, LEN(ESPORTS!H9)), """") ) "),"") | I9: =IFERROR(__xludf.DUMMYFUNCTION("TEXTJOIN( CHAR(10) & CHAR(10), TRUE, IFERROR(ARRAYFORMULA(TEXT(FILTER(WSO!F9, LEN(WSO!F9)), ""h:mm AM/PM"")), """"), IFERROR(ARRAYFORMULA(TEXT(FILTER(MSO!F9, LEN(MSO!F9)), ""h:mm AM/PM"")), """"), IFERROR(ARRAYFORMULA(TEXT(FILTER(FH!F9, LEN(FH!F"&"9)), ""h:mm AM/PM"")), """"), IFERROR(ARRAYFORMULA(TEXT(FILTER(MGOLF!F9, LEN(MGOLF!F9)), ""h:mm AM/PM"")), """"), IFERROR(ARRAYFORMULA(TEXT(FILTER(Football!F9, LEN(Football!F9)), ""h:mm AM/PM"")), """"), IFERROR(ARRAYFORMULA(TEXT(FILTER(WVB!F9, LEN("&"WVB!F9)), ""h:mm AM/PM"")), """"), IFERROR(ARRAYFORMULA(TEXT(FILTER(XC!F9, LEN(XC!F9)), ""h:mm AM/PM"")), """"), IFERROR(ARRAYFORMULA(TEXT(FILTER(SWIMMING!F9, LEN(SWIMMING!F9)), ""h:mm AM/PM"")), """"), IFERROR(ARRAYFORMULA(TEXT(FILTER(WTEN!F9, LEN("&"WTEN!F9)), ""h:mm AM/PM"")), """"), IFERROR(ARRAYFORMULA(TEXT(FILTER(TF!F9, LEN(TF!F9)), ""h:mm AM/PM"")), """"), IFERROR(ARRAYFORMULA(TEXT(FILTER(WGOLF!F9, LEN(WGOLF!F9)), ""h:mm AM/PM"")), """"), IFERROR(ARRAYFORMULA(TEXT(FILTER(WBB!F9, LEN(WBB!F9"&")), ""h:mm AM/PM"")), """"), IFERROR(ARRAYFORMULA(TEXT(FILTER(MBB!F9, LEN(MBB!F9)), ""h:mm AM/PM"")), """"), IFERROR(ARRAYFORMULA(TEXT(FILTER(WLAX!F9, LEN(WLAX!F9)), ""h:mm AM/PM"")), """"), IFERROR(ARRAYFORMULA(TEXT(FILTER(MLAX!F9, LEN(MLAX!F9)), "&"""h:mm AM/PM"")), """"), IFERROR(ARRAYFORMULA(TEXT(FILTER(SOFT!F9, LEN(SOFT!F9)), ""h:mm AM/PM"")), """"), IFERROR(ARRAYFORMULA(TEXT(FILTER(BASE!F9, LEN(BASE!F9)), ""h:mm AM/PM"")), """"), IFERROR(ARRAYFORMULA(TEXT(FILTER(ESPORTS!F9, LEN(ESPORTS!F9)"&"), ""h:mm AM/PM"")), """") ) "),"") | J9: =IFERROR(__xludf.DUMMYFUNCTION("IFERROR( TEXTJOIN( CHAR(10) & CHAR(10), TRUE, FILTER( FLATTEN({ WSO!P9; MSO!P9; FH!P9; MGOLF!P9; Football!P9; WVB!P9; XC!P9; SWIMMING!P9; WTEN!P9; TF!P9; WGOLF!P9;"&" WBB!P9; MBB!P9; WLAX!P9; MLAX!P9; SOFT!P9; BASE!P9; ESPORTS!P9 }), (FLATTEN({ WSO!P9; MSO!P9; FH!P9; MGOLF!P9; Football!P9; WVB!P9; XC!P9; "&"SWIMMING!P9; WTEN!P9; TF!P9; WGOLF!P9; WBB!P9; MBB!P9; WLAX!P9; MLAX!P9; SOFT!P9; BASE!P9; ESPORTS!P9 }) <> """") * (FLATTEN({ WSO!P9; MSO!P9; FH!P9; "&" MGOLF!P9; Football!P9; WVB!P9; XC!P9; SWIMMING!P9; WTEN!P9; TF!P9; WGOLF!P9; WBB!P9; MBB!P9; WLAX!P9; MLAX!P9; SOFT!P9; BASE!P9; ESPORTS!P9 }) <> ""S"&"tatus"") ) ), """" ) "),"")
A10: 9 | C10: 46243 | D10: =text(C10,"dddd") -> Sunday | E10: =TEXTJOIN( CHAR(10) & CHAR(10), TRUE, IFERROR(WSO!E10, ""), IFERROR(MSO!E10, ""), IFERROR(FH!E10, ""), IFERROR(MGOLF!E10, ""), IFERROR(Football!E10, ""), IFERROR(WVB!E10, ""), IFERROR(XC!E10, ""), IFERROR(SWIMMING!E10, ""), IFERROR(WTEN!E10, ""), IFERROR(TF!E10, ""), IFERROR(WGOLF!E10, ""), IFERROR(WBB!E10, ""), IFERROR(MBB!E10, ""), IFERROR(WLAX!E10, ""), IFERROR(MLAX!E10, ""), IFERROR(SOFT!E10, ""), IFERROR(BASE!E10, ""), IFERROR(ESPORTS!E10, "") ) | F10: =IFERROR(__xludf.DUMMYFUNCTION("TEXTJOIN( CHAR(10) & CHAR(10), TRUE, IFERROR(TEXT(FILTER(WSO!F10, LEN(WSO!F10)), ""h:mm AM/PM""), """"), IFERROR(TEXT(FILTER(MSO!F10, LEN(MSO!F10)), ""h:mm AM/PM""), """"), IFERROR(TEXT(FILTER(FH!F10, LEN(FH!F10)), ""h:mm AM/PM""), """"), IFER"&"ROR(TEXT(FILTER(MGOLF!F10, LEN(MGOLF!F10)), ""h:mm AM/PM""), """"), IFERROR(TEXT(FILTER(Football!F10, LEN(Football!F10)), ""h:mm AM/PM""), """"), IFERROR(TEXT(FILTER(WVB!F10, LEN(WVB!F10)), ""h:mm AM/PM""), """"), IFERROR(TEXT(FILTER(XC!F10, LEN(XC!"&"F10)), ""h:mm AM/PM""), """"), IFERROR(TEXT(FILTER(SWIMMING!F10, LEN(SWIMMING!F10)), ""h:mm AM/PM""), """"), IFERROR(TEXT(FILTER(WTEN!F10, LEN(WTEN!F10)), ""h:mm AM/PM""), """"), IFERROR(TEXT(FILTER(TF!F10, LEN(TF!F10)), ""h:mm AM/PM""), """"), IF"&"ERROR(TEXT(FILTER(WGOLF!F10, LEN(WGOLF!F10)), ""h:mm AM/PM""), """"), IFERROR(TEXT(FILTER(WBB!F10, LEN(WBB!F10)), ""h:mm AM/PM""), """"), IFERROR(TEXT(FILTER(MBB!F10, LEN(MBB!F10)), ""h:mm AM/PM""), """"), IFERROR(TEXT(FILTER(WLAX!F10, LEN(WLAX!F10)"&"), ""h:mm AM/PM""), """"), IFERROR(TEXT(FILTER(MLAX!F10, LEN(MLAX!F10)), ""h:mm AM/PM""), """"), IFERROR(TEXT(FILTER(SOFT!F10, LEN(SOFT!F10)), ""h:mm AM/PM""), """"), IFERROR(TEXT(FILTER(BASE!F10, LEN(BASE!F10)), ""h:mm AM/PM""), """"), IFERROR(TE"&"XT(FILTER(ESPORTS!F10, LEN(ESPORTS!F10)), ""h:mm AM/PM""), """") ) "),"") | G10: =IFERROR(__xludf.DUMMYFUNCTION("TEXTJOIN( CHAR(10) & CHAR(10), TRUE, IFERROR(FILTER(WSO!G10, LEN(WSO!G10)), """"), IFERROR(FILTER(MSO!G10, LEN(MSO!G10)), """"), IFERROR(FILTER(FH!G10, LEN(FH!G10)), """"), IFERROR(FILTER(MGOLF!G10, LEN(MGOLF!G10)), """"), IFERROR(FILTER(Foo"&"tball!G10, LEN(Football!G10)), """"), IFERROR(FILTER(WVB!G10, LEN(WVB!G10)), """"), IFERROR(FILTER(XC!G10, LEN(XC!G10)), """"), IFERROR(FILTER(SWIMMING!G10, LEN(SWIMMING!G10)), """"), IFERROR(FILTER(WTEN!G10, LEN(WTEN!G10)), """"), IFERROR(FILTE"&"R(TF!G10, LEN(TF!G10)), """"), IFERROR(FILTER(WGOLF!G10:G1000, LEN(WGOLF!G10)), """"), IFERROR(FILTER(WBB!G10, LEN(WBB!G10)), """"), IFERROR(FILTER(MBB!G10, LEN(MBB!G10)), """"), IFERROR(FILTER(WLAX!G10, LEN(WLAX!G10)), """"), IFERROR(FILTER(MLA"&"X!G10, LEN(MLAX!G10)), """"), IFERROR(FILTER(SOFT!G10, LEN(SOFT!G10)), """"), IFERROR(FILTER(BASE!G10, LEN(BASE!G10)), """"), IFERROR(FILTER(ESPORTS!G10, LEN(ESPORTS!G10)), """") ) "),"") | H10: =IFERROR(__xludf.DUMMYFUNCTION("TEXTJOIN( CHAR(10) & CHAR(10), TRUE, IFERROR(FILTER(WSO!H10, LEN(WSO!H10)), """"), IFERROR(FILTER(MSO!H10, LEN(MSO!H10)), """"), IFERROR(FILTER(FH!H10, LEN(FH!H10)), """"), IFERROR(FILTER(MGOLF!H10, LEN(MGOLF!H10)), """"), IFERROR(FILTER(Foo"&"tball!H10, LEN(Football!H10)), """"), IFERROR(FILTER(WVB!H10, LEN(WVB!H10)), """"), IFERROR(FILTER(XC!H10, LEN(XC!H10)), """"), IFERROR(FILTER(SWIMMING!H10, LEN(SWIMMING!H10)), """"), IFERROR(FILTER(WTEN!H10, LEN(WTEN!H10)), """"), IFERROR(FILTE"&"R(TF!H10, LEN(TF!H10)), """"), IFERROR(FILTER(WGOLF!H10, LEN(WGOLF!H10)), """"), IFERROR(FILTER(WBB!H10, LEN(WBB!H10)), """"), IFERROR(FILTER(MBB!H10, LEN(MBB!H10)), """"), IFERROR(FILTER(WLAX!H10, LEN(WLAX!H10)), """"), IFERROR(FILTER(MLAX!H10,"&" LEN(MLAX!H10)), """"), IFERROR(FILTER(SOFT!H10, LEN(SOFT!H10)), """"), IFERROR(FILTER(BASE!H10, LEN(BASE!H10)), """"), IFERROR(FILTER(ESPORTS!H10, LEN(ESPORTS!H10)), """") ) "),"") | I10: =IFERROR(__xludf.DUMMYFUNCTION("TEXTJOIN( CHAR(10) & CHAR(10), TRUE, IFERROR(ARRAYFORMULA(TEXT(FILTER(WSO!F10, LEN(WSO!F10)), ""h:mm AM/PM"")), """"), IFERROR(ARRAYFORMULA(TEXT(FILTER(MSO!F10, LEN(MSO!F10)), ""h:mm AM/PM"")), """"), IFERROR(ARRAYFORMULA(TEXT(FILTER(FH!F10, LEN"&"(FH!F10)), ""h:mm AM/PM"")), """"), IFERROR(ARRAYFORMULA(TEXT(FILTER(MGOLF!F10, LEN(MGOLF!F10)), ""h:mm AM/PM"")), """"), IFERROR(ARRAYFORMULA(TEXT(FILTER(Football!F10, LEN(Football!F10)), ""h:mm AM/PM"")), """"), IFERROR(ARRAYFORMULA(TEXT(FILTER(WV"&"B!F10, LEN(WVB!F10)), ""h:mm AM/PM"")), """"), IFERROR(ARRAYFORMULA(TEXT(FILTER(XC!F10, LEN(XC!F10)), ""h:mm AM/PM"")), """"), IFERROR(ARRAYFORMULA(TEXT(FILTER(SWIMMING!F10, LEN(SWIMMING!F10)), ""h:mm AM/PM"")), """"), IFERROR(ARRAYFORMULA(TEXT(FILT"&"ER(WTEN!F10, LEN(WTEN!F10)), ""h:mm AM/PM"")), """"), IFERROR(ARRAYFORMULA(TEXT(FILTER(TF!F10, LEN(TF!F10)), ""h:mm AM/PM"")), """"), IFERROR(ARRAYFORMULA(TEXT(FILTER(WGOLF!F10, LEN(WGOLF!F10)), ""h:mm AM/PM"")), """"), IFERROR(ARRAYFORMULA(TEXT(FIL"&"TER(WBB!F10, LEN(WBB!F10)), ""h:mm AM/PM"")), """"), IFERROR(ARRAYFORMULA(TEXT(FILTER(MBB!F10, LEN(MBB!F10)), ""h:mm AM/PM"")), """"), IFERROR(ARRAYFORMULA(TEXT(FILTER(WLAX!F10, LEN(WLAX!F10)), ""h:mm AM/PM"")), """"), IFERROR(ARRAYFORMULA(TEXT(FILT"&"ER(MLAX!F10, LEN(MLAX!F10)), ""h:mm AM/PM"")), """"), IFERROR(ARRAYFORMULA(TEXT(FILTER(SOFT!F10, LEN(SOFT!F10)), ""h:mm AM/PM"")), """"), IFERROR(ARRAYFORMULA(TEXT(FILTER(BASE!F10, LEN(BASE!F10)), ""h:mm AM/PM"")), """"), IFERROR(ARRAYFORMULA(TEXT(F"&"ILTER(ESPORTS!F10, LEN(ESPORTS!F10)), ""h:mm AM/PM"")), """") ) "),"") | J10: =IFERROR(__xludf.DUMMYFUNCTION("IFERROR( TEXTJOIN( CHAR(10) & CHAR(10), TRUE, FILTER( FLATTEN({ WSO!P10; MSO!P10; FH!P10; MGOLF!P10; Football!P10; WVB!P10; XC!P10; SWIMMING!P10; WTEN!P10; TF!P10; "&" WGOLF!P10; WBB!P10; MBB!P10; WLAX!P10; MLAX!P10; SOFT!P10; BASE!P10; ESPORTS!P10 }), (FLATTEN({ WSO!P10; MSO!P10; FH!P10; MGOLF!P10; Football!P10; WVB!P1"&"0; XC!P10; SWIMMING!P10; WTEN!P10; TF!P10; WGOLF!P10; WBB!P10; MBB!P10; WLAX!P10; MLAX!P10; SOFT!P10; BASE!P10; ESPORTS!P10 }) <> """") * (FLATTEN({ WSO!P"&"10; MSO!P10; FH!P10; MGOLF!P10; Football!P10; WVB!P10; XC!P10; SWIMMING!P10; WTEN!P10; TF!P10; WGOLF!P10; WBB!P10; MBB!P10; WLAX!P10; MLAX!P10; SOFT!P"&"10; BASE!P10; ESPORTS!P10 }) <> ""Status"") ) ), """" ) "),"")
